<?xml version="1.0"?>
<robot xmlns:xacro="http://ros.org/wiki/xacro" name="scara">

  <xacro:property name="PI" value="3.14159"/>
  <xacro:property name="use_paused_simulation" value="false" />
  
  <!-- World and Dummy Links -->
  <!-- BASE LINK with 1.6 m height -->
  <link name="base_link">
    <visual>
      <origin xyz="0 0 0.1" rpy="0 0 0"/> <!-- Half of 1.6 m -->
      <geometry>
	<cylinder radius="0.1" length="0.2"/>
      </geometry>
      <material name="grey">
        <color rgba="0.6 0.6 0.6 1.0"/>
      </material>
    </visual>
    <collision>
      <origin xyz="0 0 0.1" rpy="0 0 0"/>
      <geometry>
	<cylinder radius="0.1" length="0.2"/>
      </geometry>
      <surface>
	<friction>
	  <ode>
	    <mu>100</mu>
	    <mu2>50</mu2>
	  </ode>
	</friction>
      </surface>
    </collision>
    <inertial>
      <mass value="5.0"/>
      <inertia ixx="0.1" iyy="0.1" izz="0.1" ixy="0.0" ixz="0.0" iyz="0.0"/>
    </inertial>
  </link>

<!-- JOINT 1: Positioned on top of tall base -->
  <joint name="joint1" type="revolute">
    <parent link="base_link"/>
    <child link="link1"/>
    <origin xyz="0 0 0.2" rpy="0 0 0"/> <!-- Moved from 0.025 to 1.6 -->
    <axis xyz="0 0 1"/>
    <limit lower="-3.14" upper="3.14" effort="10.0" velocity="1.0"/>
    <dynamics damping="10" friction="1.0"/>
  </joint>
  
  <link name="link1">
    <visual>
      <geometry>
        <box size="0.4 0.05 0.05"/>
      </geometry>
      <origin xyz="0.2 0 0"/>
      <material name="blue">
        <color rgba="0 0 1 1"/>
      </material>
    </visual>
    <collision>
      <geometry>
        <box size="0.4 0.05 0.05"/>
      </geometry>
      <origin xyz="0.2 0 0"/>
    </collision>
    <inertial>
      <mass value="5.0"/>
      <origin xyz="0.2 0 0"/>
      <inertia ixx="0.002" iyy="0.002" izz="0.002"
               ixy="0.0" ixz="0.0" iyz="0.0"/>
    </inertial>
  </link>

  <!-- JOINT 2 -->
  <joint name="joint2" type="revolute">
    <parent link="link1"/>
    <child link="link2"/>
    <origin xyz="0.4 0 0" rpy="0 0 0"/>
    <axis xyz="0 0 1"/>
    <limit lower="-3.14" upper="3.14" effort="10.0" velocity="1.0"/>
    <dynamics damping="10" friction="1.0"/>
  </joint>

  <link name="link2">
    <visual>
      <geometry>
        <box size="0.3 0.05 0.05"/>
      </geometry>
      <origin xyz="0.15 0 0"/>
      <material name="green">
        <color rgba="0 1 0 1"/>
      </material>
    </visual>
    <collision>
      <geometry>
        <box size="0.3 0.05 0.05"/>
      </geometry>
      <origin xyz="0.15 0 0"/>
    </collision>
    <inertial>
      <mass value="7"/>
      <origin xyz="0.15 0 0"/>
      <inertia ixx="0.0015" iyy="0.0015" izz="0.0015"
               ixy="0.0" ixz="0.0" iyz="0.0"/>
    </inertial>
  </link>

  <!-- JOINT 3 -->
  <joint name="joint3" type="prismatic">
    <parent link="link2"/>
    <child link="link3"/>
    <origin xyz="0.3 0 0" rpy="0 0 0"/>
    <axis xyz="0 0 1"/>
    <limit lower="-0.2" upper="0" effort="10.0" velocity="0.2"/>
    <dynamics damping="10" friction="1.0"/>
  </joint>

  <link name="link3">
    <visual>
      <geometry>
        <cylinder radius="0.03" length="0.2"/>
      </geometry>
      <origin xyz="0 0 -0.1"/>
      <material name="yellow">
        <color rgba="1 1 0 1"/>
      </material>
    </visual>
    <collision>
      <geometry>
        <cylinder radius="0.03" length="0.2"/>
      </geometry>
      <origin xyz="0 0 -0.1"/>
    </collision>
    <inertial>
      <mass value="5"/>
      <origin xyz="0 0 -0.1"/>
      <inertia ixx="0.0003" iyy="0.0003" izz="0.0003"
               ixy="0.0" ixz="0.0" iyz="0.0"/>
    </inertial>
  </link>

  <!-- Fixed gripper -->
  <joint name="gripper_joint" type="fixed">
    <parent link="link3"/>
    <child link="gripper"/>
    <origin xyz="0 0 -0.2" rpy="0 0 0"/>
  </joint>

  <link name="gripper">
    <visual>
      <geometry>
        <box size="0.05 0.05 0.05"/>
      </geometry>
      <material name="red">
        <color rgba="1 0 0 1"/>
      </material>
    </visual>
    <collision>
      <geometry>
        <box size="0.05 0.05 0.05"/>
      </geometry>
    </collision>
    <inertial>
      <mass value="0.1"/>
      <inertia ixx="0.001" ixy="0.0" ixz="0.0"
               iyy="0.001" iyz="0.0"
               izz="0.001"/>
    </inertial>
  </link>

  <!-- ROS2 Control Hardware Interface -->
  <ros2_control name="scara_control" type="system">
    <hardware>
      <plugin>gazebo_ros2_control/GazeboSystem</plugin>
      <param name="robot_description">robot_description</param>
    </hardware>
  
    <joint name="joint1">
      <command_interface name="position"/>
      <state_interface name="position"/>
      <state_interface name="velocity"/>
    </joint>
  
    <joint name="joint2">
      <command_interface name="position"/>
      <state_interface name="position"/>
      <state_interface name="velocity"/>
    </joint>
  
    <joint name="joint3">
      <command_interface name="position"/>
      <state_interface name="position"/>
      <state_interface name="velocity"/>
    </joint>
  </ros2_control>

  <gazebo>
    <plugin name="gazebo_ros_control" filename="libgazebo_ros2_control.so">
      <parameters>config/scara_controllers.yaml</parameters>
    </plugin>
    <physics type="ode">
      <max_step_size>0.0001</max_step_size>
      <real_time_update_rate>2000</real_time_update_rate>
      <solver>
        <type>quick</type>
        <iters>100</iters>
        <sor>1.4</sor>
      </solver>
      <constraints>
        <cfm>0.00001</cfm>
        <erp>0.2</erp>
        <contact_max_correcting_vel>1000</contact_max_correcting_vel>
        <contact_surface_layer>0.001</contact_surface_layer>
      </constraints>
    </physics>
  </gazebo>
</robot>
