<?xml version="1.0"?>
<robot xmlns:xacro="http://www.ros.org/wiki/xacro" name="conveyor_belt">
  <link name="world1"/>

  <joint name="world_to_conveyor" type="fixed">
    <parent link="world1"/>
    <child link="conv_base_link"/>
    <origin xyz="0 0 0.1" rpy="0 0 0"/>
  </joint>

  <!-- Conveyor Belt Base -->
  <link name="conv_base_link">
    <visual>
      <origin xyz="0 0 0" rpy="0 0 0"/>
      <geometry>
        <box size="2.0 0.5 0.1"/>
      </geometry>
      <material name="gray"/>
    </visual>
    <collision>
      <origin xyz="0 0 0" rpy="0 0 0"/>
      <geometry>
        <box size="2.0 0.5 0.1"/>
      </geometry>
    </collision>
    <inertial>
      <mass value="50.0"/>
      <inertia ixx="0.1" ixy="0.0" ixz="0.0" iyy="0.1" iyz="0.0" izz="0.1"/>
    </inertial>
  </link>

  <!-- Conveyor Belt Motor Joint -->
  <joint name="conveyor_motor" type="revolute">
    <parent link="conv_base_link"/>
    <child link="conveyor_motor_link"/>
    <origin xyz="0 0 0.1" rpy="0 0 0"/>
    <axis xyz="0 0 1"/>
    <limit effort="10" velocity="0.5" lower="0" upper="6.28"/>
    <dynamics damping="0.1" friction="0.1"/>
  </joint>

  <!-- Conveyor Motor Link -->
  <link name="conveyor_motor_link">
    <visual>
      <origin xyz="0 0 0" rpy="0 0 0"/>
      <geometry>
        <cylinder radius="0.1" length="0.1"/>
      </geometry>
      <material name="gray"/>
    </visual>
    <collision>
      <origin xyz="0 0 0" rpy="0 0 0"/>
      <geometry>
        <cylinder radius="0.1" length="0.1"/>
      </geometry>
    </collision>
    <inertial>
      <mass value="5.0"/>
      <inertia ixx="0.01" ixy="0.0" ixz="0.0" iyy="0.01" iyz="0.0" izz="0.01"/>
    </inertial>
  </link>


  <ros2_control name="ConveyorHardware" type="system">
    <hardware>
      <plugin>fake_components/GenericSystem</plugin>
      <param name="update_rate">50</param>
      <param name="joint_command_interface">velocity</param>
      <param name="joint_state_interface">position</param>
    </hardware>

    <joint name="conveyor_motor">
      <command_interface name="velocity"/>
      <state_interface name="position"/>
      <state_interface name="velocity"/>
    </joint>
  </ros2_control>

</robot>

